<mujoco model="tita">
  <compiler angle="radian" meshdir="/home/ubuntu/miniconda3/envs/tianshou/lib/python3.12/site-packages/gymnasium/envs/mujoco/assets/meshes/tita" autolimits="true"/>

  <default>
    <default class="robot">
      <geom condim="1" contype="0" conaffinity="1"/>
      <joint armature="0.005" damping="0.5"/>
      <position inheritrange="1" kp="35" kv="10"/>

      <default class="joint_1">
        <joint range="-0.785398 0.785398" frictionloss="0.3" />
        <position forcerange="-60 60" />
      </default>
      <default class="joint_2">
        <joint range="-1.919862 3.490659" frictionloss="0.3" />
        <position forcerange="-60 60" />
      </default>
      <default class="joint_3">
        <joint range="-2.670354 -0.698132" frictionloss="0.3" />
        <position forcerange="-60 60" />
      </default>
      <default class="joint_4">
        <joint range="-999999 999999" frictionloss="0.3" />
        <position forcerange="-15 15" />
      </default>
      <default class="visual">
        <geom material="visualgeom" contype="0" conaffinity="0" group="2" />
      </default>
      <default class="collision">
        <geom material="collision_material" condim="3" contype="0" conaffinity="1" priority="1" group="1" solref="0.005 1" solimp="0.99 0.999 1e-05" friction="1 0.01 0.01" />
      </default>
    </default>
  </default>

  <asset>
    <material name="black" rgba="0.19607843137254902 0.19607843137254902 0.19607843137254902 1.0" />
    <material name="blue" rgba="0.0 0.0 0.8 1.0" />
    <material name="green" rgba="0.0 0.8 0.0 1.0" />
    <material name="grey" rgba="0.2 0.2 0.2 1.0" />
    <material name="silver" rgba="0.9137254901960784 0.9137254901960784 0.8470588235294118 1.0" />
    <material name="orange" rgba="1.0 0.4235294117647059 0.0392156862745098 1.0" />
    <material name="brown" rgba="0.8705882352941177 0.8117647058823529 0.7647058823529411 1.0" />
    <material name="red" rgba="0.8 0.0 0.0 1.0" />
    <material name="white" rgba="1.0 1.0 1.0 1.0" />
    <material name="default_material" rgba="0.7 0.7 0.7 1" />
    <material name="collision_material" rgba="1.0 0.28 0.1 0.9" />
    <mesh name="base_link.stl" file="base_link.stl" />
    <mesh name="left_leg_1.stl" file="left_leg_1.stl" />
    <mesh name="left_leg_2.stl" file="left_leg_2.stl" />
    <mesh name="left_leg_3.stl" file="left_leg_3.stl" />
    <mesh name="left_leg_4.stl" file="left_leg_4.stl" />
    <mesh name="right_leg_1.stl" file="right_leg_1.stl" />
    <mesh name="right_leg_2.stl" file="right_leg_2.stl" />
    <mesh name="right_leg_3.stl" file="right_leg_3.stl" />
    <mesh name="right_leg_4.stl" file="right_leg_4.stl" />
  <texture name="grid" type="2d" builtin="checker" rgb1=".1 .2 .3" rgb2=".2 .3 .4" width="300" height="300" mark="none" /><material name="grid" texture="grid" texrepeat="1 1" texuniform="true" reflectance=".2" />
  </asset>

  <worldbody>
    <!--light name="light" pos="0 0 3" /><geom name="floor" type="plane" pos="0 0 -.5" size="2 2 .1" material="grid" /-->
    <!--body name="base_link" pos="0.00000000 0.00000000 0.41700019" quat="1 0 0 0" childclass="robot"-->
    <body name="base_link" pos="0.00000000 0.00000000 0.49" quat="1 0 0 0" childclass="robot">
      <inertial mass="9.852" pos="0.021763 0.0019065 0.027873" fullinertia="0.061855 0.036934 0.071232 -2.6029E-05 0.00081082 -1.7269E-05" /> 
      <freejoint name="floating_base" />
      <geom name="base_link_collision" pos="0 0 0.017" quat="1.0 0.0 0.0 0.0" type="box" size="0.235 0.15 0.095" class="collision" />
      <geom name="base_link_visual" pos="0 0 0" quat="1.0 0.0 0.0 0.0" material="default_material" type="mesh" mesh="base_link.stl" class="visual" />
      <body name="spad" pos="0.24052 -0.0019 0.064455" quat="0.32105535300536925 0.6300171614361358 0.6300194756226387 0.3210565323096963" />
      <body name="spad1" pos="0.21953 -0.0019 -0.030142" quat="0.17822474632683968 0.6842763354041859 0.6842788488961296 0.1782254009840898" />
      <body name="left_camera" pos="0.23416 0.075 0.04036" quat="0.4999981633974483 0.49999999999662686 0.5000018366025516 0.49999999999662686" />
      <body name="ch201" pos="0.23782 0 0.018636" quat="0.5896590127793068 0.3902568539379952 0.39025828743409546 0.5896611787217797" />
      <body name="right_camara" pos="0.23416 -0.075001 0.04036" quat="0.4999981633974483 0.49999999999662686 0.5000018366025516 0.49999999999662686" />
      <body name="left_leg_1" pos="0 0.0895 0" quat="0.499998 0.5 0.500002 0.5">
        <joint name="joint_left_leg_1" type="hinge" class="joint_1" pos="0 0 0" axis="0 0 1"/>
        <inertial pos="0.0016025 5.0253e-05 0.000638" quat="0.999804 -0.0010502 -0.019755 -9.57202e-05" mass="2.064" diaginertia="0.00430758 0.0029982 0.00226711"/>
        <geom name="left_leg_1_visual" pos="0 0 0" quat="1.0 0.0 0.0 0.0" material="default_material" type="mesh" mesh="left_leg_1.stl" class="visual" />
        <body name="left_leg_2" pos="0.1426 0 0" quat="0.499998 -0.5 0.500002 -0.5">
          <joint name="joint_left_leg_2" type="hinge" class="joint_2" pos="0 0 0" axis="0 0 1" />
          <inertial pos="0.021763 0.0019069 -0.027868" quat="-0.00931458 0.711777 0.0101084 0.702271" mass="3.0984" diaginertia="0.00883636 0.00648624 0.00297469"/>
          <geom name="left_leg_2_visual" pos="0 0 0" quat="1.0 0.0 0.0 0.0" material="default_material" type="mesh" mesh="left_leg_2.stl" class="visual" />
          <body name="left_leg_3" pos="0.2 0 0">
            <joint name="joint_left_leg_3" type="hinge" class="joint_3" pos="0 0 0" axis="0 0 1" />
            <inertial pos="0.095348 0.011698 0.001838" quat="0.03753 0.692169 -0.047281 0.719207" mass="0.57244" diaginertia="0.00342536 0.00324384 0.000258551"/>
            <geom name="left_leg_3_collision" pos="0.1 0.021 -0.002" quat="0.997856 0 0 -0.0654532" type="box" size="0.1 0.035 0.025" class="collision" />
            <geom name="left_leg_3_visual" pos="0 0 0" quat="1.0 0.0 0.0 0.0" material="default_material" type="mesh" mesh="left_leg_3.stl" class="visual" />
            <body name="left_leg_4" pos="0.2 0 0.0514">
              <joint name="joint_left_leg_4" type="hinge" class="joint_4"  axis="0 0 1" />
              <inertial pos="-2.267e-06 -1.6471e-06 -0.00095616" quat="0.457615 0.539031 -0.457649 0.539066" mass="1.5094" diaginertia="0.0069049 0.00354775 0.00350415"/>
              <geom name="left_leg_4_collision" pos="0 0 0" quat="1.0 0.0 0.0 0.0" type="cylinder" size="0.0925 0.017" class="collision" />
              <geom name="left_leg_4_visual" pos="0 0 0" quat="1.0 0.0 0.0 0.0" material="default_material" type="mesh" mesh="left_leg_4.stl" class="visual" />
              <site name="left_leg_4_site" pos="0 0 0" size="0.01" rgba="1 0 0 0.5"/>
            </body>
          </body>
        </body>
      </body>
      <body name="right_leg_1" pos="0 -0.0895 0" quat="0.499998 0.5 0.500002 0.5">
        <joint name="joint_right_leg_1" type="hinge" class="joint_1" pos="0 0 0" axis="0 0 1"/>
        <inertial pos="-0.0016025 5.0253e-05 0.00063801" quat="0.999804 -0.00104426 0.019755 9.54715e-05" mass="2.064" diaginertia="0.00430758 0.0029982 0.00226711"/>
        <geom name="right_leg_1_visual" pos="0 0 0" quat="1.0 0.0 0.0 0.0" material="default_material" type="mesh" mesh="right_leg_1.stl" class="visual" />
        <body name="right_leg_2" pos="-0.1426 0 0" quat="0.499998 -0.5 0.500002 -0.5">
          <joint name="joint_right_leg_2" type="hinge" class="joint_2" pos="0 0 0" axis="0 0 1"/>
          <inertial pos="0.021763 0.0019065 0.027873" quat="-0.0101102 0.702272 0.00931581 0.711776" mass="3.0987" diaginertia="0.00883636 0.00648624 0.00297469"/>
          <geom name="right_leg_2_visual" pos="0 0 0" quat="1.0 0.0 0.0 0.0" material="default_material" type="mesh" mesh="right_leg_2.stl" class="visual" />
          <body name="right_leg_3" pos="0.2 0 0" quat="1.0 0.0 0.0 0.0">
            <joint name="joint_right_leg_3" type="hinge" class="joint_3" pos="0 0 0" axis="0 0 1" />
            <inertial pos="0.095348 0.011698 -0.001838" quat="0.047281 0.719207 -0.03753 0.692169" mass="0.57244" diaginertia="0.00342536 0.00324384 0.000258551"/>
            <geom name="right_leg_3_collision" pos="0.1 0.021 -0.002" quat="0.997856 0 0 -0.0654532" type="box" size="0.1 0.035 0.025" class="collision" />
            <geom name="right_leg_3_visual" pos="0 0 0" quat="1.0 0.0 0.0 0.0" material="default_material" type="mesh" mesh="right_leg_3.stl" class="visual" />
            <body name="right_leg_4" pos="0.2 0 -0.0514" quat="1.0 0.0 0.0 0.0">
              <joint name="joint_right_leg_4" type="hinge" class="joint_4" pos="0 0 0" axis="0 0 1" />
              <inertial pos="-2.3798e-06 -1.5854e-06 0.00095595" quat="0.457221 0.539429 -0.457186 0.539395" mass="1.5094" diaginertia="0.0069047 0.00354767 0.00350403"/>
              <geom name="right_leg_4_collision" pos="0 0 0" quat="1.0 0.0 0.0 0.0" type="cylinder" size="0.0925 0.017" class="collision" />
              <geom name="right_leg_4_visual" pos="0 0 0" quat="1.0 0.0 0.0 0.0" material="default_material" type="mesh" mesh="right_leg_4.stl" class="visual" />
              <site name="right_leg_4_site" pos="0 0 0" size="0.01" rgba="1 0 0 0.5"/>
            </body>
          </body>
        </body>
      </body>
      <site name="base_link_site" pos="0 0 0" quat="1 0 0 0" />
      <camera name="front_camera" mode="track" fovy="90.0" quat="4.329780281177467e-17 4.329780281177466e-17 0.7071067811865475 0.7071067811865476" pos="0.0 2.0 0.5" />
      <camera name="side_camera" mode="track" fovy="90.0" quat="-0.5 -0.4999999999999999 0.5 0.5000000000000001" pos="-2.0 0.0 0.5" />
      <camera name="track" pos="0.846 -1.3 0.316" xyaxes="0.866 0.500 0.000 -0.171 0.296 0.940" mode="trackcom"/>
      <site name="imu" pos="0 0 0" quat="1 0 0 0" size="0.01" type="sphere" rgba="1 0 0 0.5" />
    </body>
  </worldbody>

  <actuator>
    <position name="joint_left_leg_1_ctrl" joint="joint_left_leg_1" class="joint_1" />
    <position name="joint_left_leg_2_ctrl" joint="joint_left_leg_2" class="joint_2" />
    <position name="joint_left_leg_3_ctrl" joint="joint_left_leg_3" class="joint_3" />
    <position name="joint_left_leg_4_ctrl" joint="joint_left_leg_4" class="joint_4" />
    <position name="joint_right_leg_1_ctrl" joint="joint_right_leg_1" class="joint_1" />
    <position name="joint_right_leg_2_ctrl" joint="joint_right_leg_2" class="joint_2" />
    <position name="joint_right_leg_3_ctrl" joint="joint_right_leg_3" class="joint_3" />
    <position name="joint_right_leg_4_ctrl" joint="joint_right_leg_4" class="joint_4" />
  </actuator>

  <contact>
    <exclude body1="left_leg_3" body2="left_leg_4" />
    <exclude body1="right_leg_3" body2="right_leg_4" />
  </contact>

  <sensor>
    <framepos name="base_link_site_pos" objtype="site" objname="base_link_site" />
    <framequat name="base_link_site_quat" objtype="site" objname="base_link_site" />
    <framelinvel name="base_link_site_linvel" objtype="site" objname="base_link_site" />
    <frameangvel name="base_link_site_angvel" objtype="site" objname="base_link_site" />
    <velocimeter name="base_link_site_vel" site="base_link_site" />
  </sensor>

  <sensor>
    <gyro site="imu" name="gyro"/>
    <velocimeter site="imu" name="local_linvel"/>
    <accelerometer site="imu" name="accelerometer"/>
    <framezaxis objtype="site" objname="imu" name="upvector"/>
    <framexaxis objtype="site" objname="imu" name="forwardvector"/>
    <framelinvel objtype="site" objname="imu" name="global_linvel"/>
    <frameangvel objtype="site" objname="imu" name="global_angvel"/>
    <framepos objtype="site" objname="imu" name="position"/>
    <framequat objtype="site" objname="imu" name="orientation"/>
    <framelinvel objtype="site" objname="left_leg_4_site"  name="left_leg_4_site_global_linvel"/>
    <framelinvel objtype="site" objname="right_leg_4_site" name="right_leg_4_site_global_linvel"/>
    <framexaxis objtype="site"  objname="left_leg_4_site"  name="left_leg_4_site_upvector"/>
    <framexaxis objtype="site"  objname="right_leg_4_site" name="right_leg_4_site_upvector"/>
    <framepos objtype="site"    objname="left_leg_4_site"  name="left_leg_4_site_pos"/>
    <framepos objtype="site"    objname="right_leg_4_site" name="right_leg_4_site_pos"/>
  </sensor>

  <statistic center="0 0 0.1" extent="0.8" meansize="0.04"/>

  <visual>
    <headlight diffuse=".8 .8 .8" ambient=".2 .2 .2" specular="1 1 1"/>
    <rgba force="1 0 0 1"/>
    <global azimuth="120" elevation="-20"/>
    <map force="0.01"/>
    <scale forcewidth="0.3" contactwidth="0.5" contactheight="0.2"/>
    <quality shadowsize="8192"/>
  </visual>

  <asset>
    <texture type="skybox" builtin="gradient" rgb1="1 1 1" rgb2="1 1 1" width="800" height="800"/>
    <texture type="2d" name="groundplane" builtin="checker" mark="edge" rgb1="1 1 1" rgb2="1 1 1" markrgb="0 0 0"
      width="300" height="300"/>
    <material name="groundplane" texture="groundplane" texuniform="true" texrepeat="5 5" reflectance="0"/>
  </asset>

  <worldbody>
    <geom name="floor" size="0 0 0.01" type="plane" material="groundplane" priority="1" friction="0.6" condim="3" contype="1" conaffinity="0"/>
  </worldbody>
  
  <keyframe>
    <key name="home" qpos="
    0 0 0.50
    1 0 0 0
    0 0.5 -1.0 0
    0 0.5 -1.0 0"
    ctrl="0.0 0.78 -1.57 0.0 0.0 0.78 -1.57 0.0"
    />
  </keyframe>

</mujoco>